[2021-05-23 04:41:05,709] {taskinstance.py:655} INFO - Dependencies all met for <TaskInstance: marketvol.create_data_directory 2021-05-23T04:41:03.187465+00:00 [queued]>
[2021-05-23 04:41:05,762] {taskinstance.py:655} INFO - Dependencies all met for <TaskInstance: marketvol.create_data_directory 2021-05-23T04:41:03.187465+00:00 [queued]>
[2021-05-23 04:41:05,764] {taskinstance.py:866} INFO - 
--------------------------------------------------------------------------------
[2021-05-23 04:41:05,765] {taskinstance.py:867} INFO - Starting attempt 1 of 3
[2021-05-23 04:41:05,767] {taskinstance.py:868} INFO - 
--------------------------------------------------------------------------------
[2021-05-23 04:41:05,795] {taskinstance.py:887} INFO - Executing <Task(BashOperator): create_data_directory> on 2021-05-23T04:41:03.187465+00:00
[2021-05-23 04:41:05,806] {standard_task_runner.py:53} INFO - Started process 3747 to run task
[2021-05-23 04:41:05,890] {logging_mixin.py:112} INFO - Running %s on host %s <TaskInstance: marketvol.create_data_directory 2021-05-23T04:41:03.187465+00:00 [running]> 208e7b2250b3
[2021-05-23 04:41:05,934] {bash_operator.py:82} INFO - Tmp dir root location: 
 /tmp
[2021-05-23 04:41:05,937] {bash_operator.py:105} INFO - Temporary script location: /tmp/airflowtmp3oq3irem/create_data_directoryu5nwyeo3
[2021-05-23 04:41:05,938] {bash_operator.py:115} INFO - Running command: 
        cd $DATAPATH ; mkdir 2021-05-23 ; cd .. ; cd finance_data ; mkdir 2021-05-23
[2021-05-23 04:41:05,949] {bash_operator.py:122} INFO - Output:
[2021-05-23 04:41:05,952] {bash_operator.py:126} INFO - mkdir: cannot create directory ‘2021-05-23’: File exists
[2021-05-23 04:41:05,956] {bash_operator.py:126} INFO - mkdir: cannot create directory ‘2021-05-23’: File exists
[2021-05-23 04:41:05,957] {bash_operator.py:130} INFO - Command exited with return code 1
[2021-05-23 04:41:05,972] {taskinstance.py:1128} ERROR - Bash command failed
Traceback (most recent call last):
  File "/usr/local/lib/python3.7/site-packages/airflow/models/taskinstance.py", line 966, in _run_raw_task
    result = task_copy.execute(context=context)
  File "/usr/local/lib/python3.7/site-packages/airflow/operators/bash_operator.py", line 134, in execute
    raise AirflowException("Bash command failed")
airflow.exceptions.AirflowException: Bash command failed
[2021-05-23 04:41:05,974] {taskinstance.py:1151} INFO - Marking task as UP_FOR_RETRY
[2021-05-23 04:41:15,568] {logging_mixin.py:112} INFO - [2021-05-23 04:41:15,567] {local_task_job.py:103} INFO - Task exited with return code 1
