[2021-05-23 04:36:30,993] {taskinstance.py:655} INFO - Dependencies all met for <TaskInstance: marketvol.create_data_directory 2021-05-21T18:00:00+00:00 [queued]>
[2021-05-23 04:36:31,020] {taskinstance.py:655} INFO - Dependencies all met for <TaskInstance: marketvol.create_data_directory 2021-05-21T18:00:00+00:00 [queued]>
[2021-05-23 04:36:31,023] {taskinstance.py:866} INFO - 
--------------------------------------------------------------------------------
[2021-05-23 04:36:31,024] {taskinstance.py:867} INFO - Starting attempt 2 of 3
[2021-05-23 04:36:31,025] {taskinstance.py:868} INFO - 
--------------------------------------------------------------------------------
[2021-05-23 04:36:31,039] {taskinstance.py:887} INFO - Executing <Task(BashOperator): create_data_directory> on 2021-05-21T18:00:00+00:00
[2021-05-23 04:36:31,044] {standard_task_runner.py:53} INFO - Started process 2213 to run task
[2021-05-23 04:36:31,141] {logging_mixin.py:112} INFO - Running %s on host %s <TaskInstance: marketvol.create_data_directory 2021-05-21T18:00:00+00:00 [running]> 208e7b2250b3
[2021-05-23 04:36:31,165] {bash_operator.py:82} INFO - Tmp dir root location: 
 /tmp
[2021-05-23 04:36:31,167] {bash_operator.py:105} INFO - Temporary script location: /tmp/airflowtmpo6r3k5qc/create_data_directoryt_4_pd9l
[2021-05-23 04:36:31,169] {bash_operator.py:115} INFO - Running command: 
        cd $DATAPATH ; mkdir 2021-05-21 ; cd .. ; cd finance_data ; mkdir 2021-05-21
[2021-05-23 04:36:31,177] {bash_operator.py:122} INFO - Output:
[2021-05-23 04:36:31,187] {bash_operator.py:126} INFO - mkdir: cannot create directory ‘2021-05-21’: File exists
[2021-05-23 04:36:31,188] {bash_operator.py:130} INFO - Command exited with return code 1
[2021-05-23 04:36:31,199] {taskinstance.py:1128} ERROR - Bash command failed
Traceback (most recent call last):
  File "/usr/local/lib/python3.7/site-packages/airflow/models/taskinstance.py", line 966, in _run_raw_task
    result = task_copy.execute(context=context)
  File "/usr/local/lib/python3.7/site-packages/airflow/operators/bash_operator.py", line 134, in execute
    raise AirflowException("Bash command failed")
airflow.exceptions.AirflowException: Bash command failed
[2021-05-23 04:36:31,201] {taskinstance.py:1151} INFO - Marking task as UP_FOR_RETRY
[2021-05-23 04:36:40,934] {logging_mixin.py:112} INFO - [2021-05-23 04:36:40,934] {local_task_job.py:103} INFO - Task exited with return code 1
