[2021-05-23 04:55:46,923] {taskinstance.py:655} INFO - Dependencies all met for <TaskInstance: marketvol.execute_query_on_data 2021-05-23T04:55:32.748724+00:00 [queued]>
[2021-05-23 04:55:46,952] {taskinstance.py:655} INFO - Dependencies all met for <TaskInstance: marketvol.execute_query_on_data 2021-05-23T04:55:32.748724+00:00 [queued]>
[2021-05-23 04:55:46,952] {taskinstance.py:866} INFO - 
--------------------------------------------------------------------------------
[2021-05-23 04:55:46,953] {taskinstance.py:867} INFO - Starting attempt 1 of 3
[2021-05-23 04:55:46,954] {taskinstance.py:868} INFO - 
--------------------------------------------------------------------------------
[2021-05-23 04:55:46,965] {taskinstance.py:887} INFO - Executing <Task(PythonOperator): execute_query_on_data> on 2021-05-23T04:55:32.748724+00:00
[2021-05-23 04:55:46,971] {standard_task_runner.py:53} INFO - Started process 1693 to run task
[2021-05-23 04:55:47,059] {logging_mixin.py:112} INFO - Running %s on host %s <TaskInstance: marketvol.execute_query_on_data 2021-05-23T04:55:32.748724+00:00 [running]> 67459f5d81d7
[2021-05-23 04:55:47,086] {logging_mixin.py:112} INFO - Execute a query on the Apple stock finance dataframe and display the results
[2021-05-23 04:55:47,087] {logging_mixin.py:112} INFO - 2021-05-23
[2021-05-23 04:55:47,089] {taskinstance.py:1128} ERROR - [Errno 2] File /usr/local/finance_data/2021-05-23/data_aapl.csv does not exist: '/usr/local/finance_data/2021-05-23/data_aapl.csv'
Traceback (most recent call last):
  File "/usr/local/lib/python3.7/site-packages/airflow/models/taskinstance.py", line 966, in _run_raw_task
    result = task_copy.execute(context=context)
  File "/usr/local/lib/python3.7/site-packages/airflow/operators/python_operator.py", line 113, in execute
    return_value = self.execute_callable()
  File "/usr/local/lib/python3.7/site-packages/airflow/operators/python_operator.py", line 118, in execute_callable
    return self.python_callable(*self.op_args, **self.op_kwargs)
  File "/usr/local/airflow/scripts/stock.py", line 21, in execute_query
    df_aapl=pd.read_csv("{}/finance_data/{}/data_aapl.csv".format(LOCALPATH,execution_date))
  File "/usr/local/airflow/.local/lib/python3.7/site-packages/pandas/io/parsers.py", line 676, in parser_f
    return _read(filepath_or_buffer, kwds)
  File "/usr/local/airflow/.local/lib/python3.7/site-packages/pandas/io/parsers.py", line 448, in _read
    parser = TextFileReader(fp_or_buf, **kwds)
  File "/usr/local/airflow/.local/lib/python3.7/site-packages/pandas/io/parsers.py", line 880, in __init__
    self._make_engine(self.engine)
  File "/usr/local/airflow/.local/lib/python3.7/site-packages/pandas/io/parsers.py", line 1114, in _make_engine
    self._engine = CParserWrapper(self.f, **self.options)
  File "/usr/local/airflow/.local/lib/python3.7/site-packages/pandas/io/parsers.py", line 1891, in __init__
    self._reader = parsers.TextReader(src, **kwds)
  File "pandas/_libs/parsers.pyx", line 374, in pandas._libs.parsers.TextReader.__cinit__
  File "pandas/_libs/parsers.pyx", line 674, in pandas._libs.parsers.TextReader._setup_parser_source
FileNotFoundError: [Errno 2] File /usr/local/finance_data/2021-05-23/data_aapl.csv does not exist: '/usr/local/finance_data/2021-05-23/data_aapl.csv'
[2021-05-23 04:55:47,099] {taskinstance.py:1151} INFO - Marking task as UP_FOR_RETRY
[2021-05-23 04:55:56,890] {logging_mixin.py:112} INFO - [2021-05-23 04:55:56,890] {local_task_job.py:103} INFO - Task exited with return code 1
